---
layout: post
title:  "Mono 내부에서 throw 를 던질 경우 onErrorResume이 동작하지 않는다?"
author: jyukki
categories: [ TEST, Webflux ]
tags: [ JAVA ]
---
> 개발 도중 Mono 내부에서 다른 이슈로 throw 가 던져졌는데, onErrorResume 을 무시하는 것을 발견했다.
> 테스트 해보자

### 기본 테스트 코드

```java
Mono<List<String>> getNameList() {

    throw new RuntimeException();
}
```

```java
@Test
void test() {

    getNameList().map(nameList -> {
                    System.out.println(nameList);
                    return nameList;
                })
                .flatMapMany(Flux::fromIterable)
                .collectList()
                .onErrorResume(e -> {
                    System.out.println("error");
                    return Mono.just(List.of("error"));
                })
                .block();
}

// java.lang.RuntimeException
```

* Mono 내부에서 throw 를 던질경우 정상적으로 onErrorResume 을 통과하지 못한다.
* 아마 내부에서 throw 로 던질 경우 Mono 에서 감지하지 못하는 듯


### Mono.error 테스트

```java
Mono<List<String>> getNameList() {

    return Mono.error(new RuntimeException("error"));
}

// 정상적으로 error 출력
```

* 이 경우에는 정상적으로 onErrorResume 을 통과했다.
* 테스트 코드는 정상인 듯


## throw 를 던져도 onErrorResume 을 통과하게 코드 수정

### 1. try-catch 로 묶어서 Mono.error 반환

```java
Mono<List<String>> getNameList() {

    try {
        throw new RuntimeException();
    } catch (Exception e) {
        return Mono.error(e);
    }
}

// 정상적으로 error 출력
```


### 2. Mono 를 defer 로 감싸기

```java
Mono<List<String>> getNameList() {

    throw new RuntimeException();
}
```
```java
@Test
void test() {

    Mono.defer(() -> getNameList())
        .map(nameList -> {
            System.out.println(nameList);
            return nameList;
        })
        .flatMapMany(Flux::fromIterable)
        .collectList()
        .onErrorResume(e -> {
            System.out.println("error");
            return Mono.just(List.of("error"));
        })
        .block();
}

// 정상적으로 error 출력
```

* 사실 이 방식이 왜 동작하는지는 잘 모르것다.
* 해결해보려고 이것저것 해보다가 되더라
* 뭐 되면 됐지 (try-catch 는 하고 싶지않았다...)

